Workbook

Sheet Nasıl Kullanılır
B2: Rasyo Hesap Şablonu
B3: Bilanço Okuma Eğitimi, ek materyal 1
B5: 1. Girdi sayfasına geçin. Üst satıra dönem adlarını yazın (örnek 2023/12, 2024/12, 2025/12). En eski dönem solda olsun.
B6: 2. Sadece sarı zeminli mavi hücreleri doldurun. Her satırın yanında rakamı tablonun hangi kaleminden alacağınız yazıyor.
B7: 3. Tüm tutarları aynı birimde girin. Şablon milyon TL varsayıyor, bin TL kullanacaksanız hepsini bin TL girin, oranlar değişmez.
B8: 4. Giderleri, vergiyi, finansman giderini, CAPEX ve temettüyü pozitif sayı olarak girin. Formüller işareti kendisi düzeltiyor.
B9: 5. Rasyolar sayfası otomatik hesaplanır. Ortalama gerektiren oranlar (devir hızları, ROE, ROA, ROIC) bir önceki dönem doluysa ortalama bakiyeyi, boşsa dönem sonu bakiyeyi kullanır.
B10: 6. Tek dönemle de çalışabilirsiniz ama trend görmek için en az iki, tercihen üç yıl girin.
B11: 7. Yorum sütunundaki eşikler genel referanstır. Perakende, enerji, holding ve banka gibi sektörlerde normlar çok farklıdır, kararınızı sektör ortalamasıyla karşılaştırarak verin.
B12: 8. Yüksek enflasyon muhasebesi (TMS 29) uygulayan şirketlerde tüm dönemlerin aynı satın alma gücüyle raporlandığından emin olun. Önceki yıl rakamlarını her zaman son raporun karşılaştırmalı sütunundan alın.
B13: 9. Kontrol sayfası bilanço denkliğini ve temel tutarlılıkları kontrol eder. Orada UYARI görürseniz girdileri yeniden gözden geçirin.
B15: Bu dosya eğitim amaçlıdır, yatırım tavsiyesi değildir.
B18: Renk kodları
B19: Mavi yazı, sarı zemin | C19: Sizin dolduracağınız girdi hücresi
B20: Siyah yazı | C20: Formül, elle değiştirmeyin
B21: Yeşil yazı | C21: Başka sayfadan gelen bağlantı

Sheet Girdi
A1: Girdi Tablosu (milyon TL)
A2: Sarı hücreleri doldurun. Giderler ve nakit çıkışları pozitif girilir.
A4: Kalem | B4: Finansal tablodaki karşılığı | C4: Dönem 1 | D4: Dönem 2 | E4: Dönem 3 | G4: Örnek (CCOLA 2025/12)
A5: Dönem adı | B5: Örnek 2023/12, en eski dönem solda | G5: 2025/12
A6: BİLANÇO
A7: Nakit ve nakit benzerleri | B7: Bilanço, Dönen Varlıklar, Nakit ve Nakit Benzerleri | G7: 30975.3
A8: Kısa vadeli finansal yatırımlar | B8: Bilanço, Dönen Varlıklar, Finansal Yatırımlar | G8: 261.6
A9: Ticari alacaklar (KV) | B9: Bilanço, Dönen Varlıklar, Ticari Alacaklar | G9: 22415.4
A10: Stoklar | B10: Bilanço, Dönen Varlıklar, Stoklar | G10: 22481.6
A11: Toplam dönen varlıklar | B11: Bilanço, Toplam Dönen Varlıklar | G11: 86689.8
A12: Maddi duran varlıklar | B12: Bilanço, Duran Varlıklar, Maddi Duran Varlıklar | G12: 87067.8
A13: Toplam varlıklar | B13: Bilanço, Toplam Varlıklar (Aktif toplamı) | G13: 224653.2
A14: Kısa vadeli finansal borçlar | B14: Bilanço, KV Yükümlülükler, Finansal Borçlar (UV borçların KV kısımları dahil) | G14: 23054.7
A15: Ticari borçlar (KV) | B15: Bilanço, KV Yükümlülükler, Ticari Borçlar | G15: 40644.7
A16: Toplam kısa vadeli yükümlülükler | B16: Bilanço, Toplam Kısa Vadeli Yükümlülükler | G16: 75172.7
A17: Uzun vadeli finansal borçlar | B17: Bilanço, UV Yükümlülükler, Finansal Borçlar | G17: 38320.2
A18: Toplam uzun vadeli yükümlülükler | B18: Bilanço, Toplam Uzun Vadeli Yükümlülükler | G18: 47470.2
... A20: Toplam özkaynaklar | B20: Bilanço, Toplam Özkaynaklar (azınlık payları dahil) | G20: 102010.3
A21: GELİR TABLOSU (giderleri pozitif girin)
A22: Hasılat | B22: Gelir Tablosu, Hasılat (Satış Gelirleri) | G22: 220428.3
A23: Satışların maliyeti | B23: Gelir Tablosu, Satışların Maliyeti (-) | G23: 142037.9
A24: Genel yönetim giderleri | B24: Gelir Tablosu, Genel Yönetim Giderleri (-) | G24: 11908.2
A25: Pazarlama, satış ve dağıtım giderleri | B25: Gelir Tablosu, Pazarlama Giderleri (-) | G25: 36722.6
A26: Araştırma ve geliştirme giderleri | B26: Gelir Tablosu, Araştırma ve Geliştirme Giderleri (-), yoksa 0 | G26: 0
A27: Esas faaliyet karı | B27: Gelir Tablosu, Esas Faaliyet Karı (Zararı) | G27: 29623.2
A28: Finansman öncesi faaliyet karı (FVÖK) | B28: Gelir Tablosu, Finansman Geliri (Gideri) Öncesi Faaliyet Karı | G28: 29554
A29: Amortisman ve itfa payları | B29: Nakit Akış Tablosu, Amortisman ve İtfa Gideri ile İlgili Düzeltmeler | G29: 8994.7
A30: Finansman giderleri | B30: Gelir Tablosu, Finansman Giderleri (-) | G30: 17588.4
A31: Vergi öncesi kar | B31: Gelir Tablosu, Sürdürülen Faaliyetler Vergi Öncesi Karı | G31: 25123.2
A32: Vergi gideri (dönem + ertelenmiş) | B32: Gelir Tablosu, Sürdürülen Faaliyetler Vergi Gideri (-) | G32: 8326.8
A33: Dönem karı (azınlık dahil) | B33: Gelir Tablosu, Dönem Karı (Zararı) | G33: 16796.5
A34: Ana ortaklık payı net kar | B34: Gelir Tablosu, Dönem Karının Dağılımı, Ana Ortaklık Payları | G34: 16571.6
A35: NAKİT AKIŞ TABLOSU (çıkışları pozitif girin)
A36: İşletme faaliyetlerinden nakit akışı | B36: Nakit Akış Tablosu, A. İşletme Faaliyetlerinden Nakit Akışları | G36: 32235.8
A37: Yatırım harcamaları (CAPEX) | B37: Nakit Akış Tablosu, Maddi ve Maddi Olmayan Duran Varlık Alımından Nakit Çıkışları | G37: 16332.1
A38: Ödenen temettü | B38: Nakit Akış Tablosu, Finansman Faaliyetleri, Ödenen Temettüler | G38: 4157.2

Sheet Rasyolar
A1: Rasyolar
A2: Bu sayfadaki tüm hücreler formüldür. Değiştirmek için Girdi sayfasını kullanın.
A4: Rasyo | B4: Formül | C4: Dönem 1 | D4: Dönem 2 | E4: Dönem 3 | F4: Nasıl yorumlanır
A5: Dönem | C5: =IF(Girdi!C5="","",Girdi!C5) | D5: =IF(Girdi!D5="","",Girdi!D5) | E5: =IF(Girdi!E5="","",Girdi!E5)
A6: LİKİDİTE ORANLARI
A7: Cari oran | B7: Dönen varlıklar / KV yükümlülükler | C7: =IFERROR(Girdi!C11/Girdi!C16,"") | D7: =IFERROR(Girdi!D11/Girdi!D16,"") | E7: =IFERROR(Girdi!E11/Girdi!E16,"") | F7: 1,5 üzeri genelde rahat, 1 altı dikkat ister. Hızlı tüketim ve perakendede 1 altı normal olabilir, çünkü tedarikçi kredisi kullanılır.
A8: Asit test oranı | B8: (Dönen varlıklar - Stoklar) / KV yükümlülükler | C8: =IFERROR((Girdi!C11-Girdi!C10)/Girdi!C16,"") | D8: =IFERROR((Girdi!D11-Girdi!D10)/Girdi!D16,"") | E8: =IFERROR((Girdi!E11-Girdi!E10)/Girdi!E16,"") | F8: Stokları satmadan KV borç ödeme gücü. 1 civarı sağlıklı kabul edilir.
A9: Nakit oranı | B9: (Nakit + KV finansal yatırımlar) / KV yükümlülükler | C9: =IFERROR((Girdi!C7+Girdi!C8)/Girdi!C16,"") | D9: =IFERROR((Girdi!D7+Girdi!D8)/Girdi!D16,"") | E9: =IFERROR((Girdi!E7+Girdi!E8)/Girdi!E16,"") | F9: En katı likidite ölçüsü. 0,2 ile 0,5 arası çoğu sanayi şirketi için yeterli.
A10: Net çalışma sermayesi (mn TL) | B10: Dönen varlıklar - KV yükümlülükler | C10: =IFERROR(Girdi!C11-Girdi!C16,"") -> 0 | D10: =IFERROR(Girdi!D11-Girdi!D16,"") -> 0 | E10: =IFERROR(Girdi!E11-Girdi!E16,"") -> 0 | F10: Negatifse şirket KV kaynakla UV varlık finanse ediyor olabilir. Trendine bakın.
A11: BORÇLULUK ORANLARI
A12: Kaldıraç oranı | B12: Toplam yükümlülükler / Toplam varlıklar | C12: =IFERROR((Girdi!C16+Girdi!C18)/Girdi!C13,"") | D12: =IFERROR((Girdi!D16+Girdi!D18)/Girdi!D13,"") | E12: =IFERROR((Girdi!E16+Girdi!E18)/Girdi!E13,"") | F12: Varlıkların ne kadarı borçla finanse edilmiş. %60 üzeri sanayide yüksek sayılır.
A13: Özkaynak / Aktif | B13: Toplam özkaynaklar / Toplam varlıklar | C13: =IFERROR(Girdi!C20/Girdi!C13,"") | D13: =IFERROR(Girdi!D20/Girdi!D13,"") | E13: =IFERROR(Girdi!E20/Girdi!E13,"") | F13: Kaldıraç oranının tamamlayıcısı. Yükseldikçe finansal risk azalır.
A14: Finansal borç / Özkaynak | B14: (KV + UV finansal borçlar) / Toplam özkaynaklar | C14: =IFERROR((Girdi!C14+Girdi!C17)/Girdi!C20,"") | D14: =IFERROR((Girdi!D14+Girdi!D17)/Girdi!D20,"") | E14: =IFERROR((Girdi!E14+Girdi!E17)/Girdi!E20,"") | F14: 1 üzeri ise şirket ortaktan çok bankayla finanse ediliyor demektir.
A15: Net borç (mn TL) | B15: KV + UV finansal borçlar - Nakit - KV finansal yatırımlar | C15: =IFERROR((Girdi!C14+Girdi!C17-Girdi!C7-Girdi!C8),"") -> 0 | D15: =IFERROR((Girdi!D14+Girdi!D17-Girdi!D7-Girdi!D8),"") -> 0 | E15: =IFERROR((Girdi!E14+Girdi!E17-Girdi!E7-Girdi!E8),"") -> 0 | F15: Negatifse şirket net nakit pozisyonunda.
A16: Net borç / FAVÖK | B16: Net borç / FAVÖK | C16: =IFERROR((Girdi!C14+Girdi!C17-Girdi!C7-Girdi!C8)/(Girdi!C22-Girdi!C23-Girdi!C24-Girdi!C25-Girdi!C26+Girdi!C29),"") | D16: =IFERROR((Girdi!D14+Girdi!D17-Girdi!D7-Girdi!D8)/(Girdi!D22-Girdi!D23-Girdi!D24-Girdi!D25-Girdi!D26+Girdi!D29),"") | E16: =IFERROR((Girdi!E14+Girdi!E17-Girdi!E7-Girdi!E8)/(Girdi!E22-Girdi!E23-Girdi!E24-Girdi!E25-Girdi!E26+Girdi!E29),"") | F16: 2 altı rahat, 2 ile 3,5 arası izlenmeli, 3,5 üzeri yüksek. Negatif değer net nakit demek.
A17: Faiz karşılama oranı | B17: FVÖK / Finansman giderleri | C17: =IFERROR(Girdi!C28/Girdi!C30,"") | D17: =IFERROR(Girdi!D28/Girdi!D30,"") | E17: =IFERROR(Girdi!E28/Girdi!E30,"") | F17: 3 üzeri rahat, 1,5 altı alarm. Finansman giderinde kur farkı varsa ayrıca dipnottan faiz giderine bakın.
A18: KV finansal borç payı | B18: KV finansal borç / Toplam finansal borç | C18: =IFERROR(Girdi!C14/(Girdi!C14+Girdi!C17),"") | D18: =IFERROR(Girdi!D14/(Girdi!D14+Girdi!D17),"") | E18: =IFERROR(Girdi!E14/(Girdi!E14+Girdi!E17),"") | F18: Yüksekse yeniden finansman riski artar. Nakit oranıyla birlikte okuyun.
A19: FAALİYET (VERİMLİLİK) ORANLARI
A20: Aktif devir hızı | B20: Hasılat / Ortalama toplam varlıklar | C20: =IFERROR(Girdi!C22/Girdi!C13,"") | D20: =IFERROR(Girdi!D22/AVERAGE(Girdi!D13,Girdi!C13),"") | E20: =IFERROR(Girdi!E22/AVERAGE(Girdi!E13,Girdi!D13),"") | F20: Her 1 TL varlıkla ne kadar satış yapıldığı. Sermaye yoğun sektörlerde düşük olur.
A21: Maddi duran varlık devir hızı | B21: Hasılat / Ortalama maddi duran varlıklar | C21: =IFERROR(Girdi!C22/Girdi!C12,"") | D21: =IFERROR(Girdi!D22/AVERAGE(Girdi!D12,Girdi!C12),"") | E21: =IFERROR(Girdi!E22/AVERAGE(Girdi!E12,Girdi!D12),"") | F21: Düşüşü yeni yatırımın henüz ciroya dönmediğini gösterebilir.
A22: Alacak devir hızı | B22: Hasılat / Ortalama ticari alacaklar | C22: =IFERROR(Girdi!C22/Girdi!C9,"") | D22: =IFERROR(Girdi!D22/AVERAGE(Girdi!D9,Girdi!C9),"") | E22: =IFERROR(Girdi!E22/AVERAGE(Girdi!E9,Girdi!D9),"") | F22: Yılda kaç kez tahsilat döngüsü tamamlanıyor.
A23: Alacak tahsil süresi (gün) | B23: 365 / Alacak devir hızı | C23: =IFERROR(365*Girdi!C9/Girdi!C22,"") | D23: =IFERROR(365*AVERAGE(Girdi!D9,Girdi!C9)/Girdi!D22,"") | E23: =IFERROR(365*AVERAGE(Girdi!E9,Girdi!D9)/Girdi!E22,"") | F23: Uzaması tahsilat sorunu veya agresif satış işareti olabilir.
A24: Stok devir hızı | B24: Satışların maliyeti / Ortalama stoklar | C24: =IFERROR(Girdi!C23/Girdi!C10,"") | D24: =IFERROR(Girdi!D23/AVERAGE(Girdi!D10,Girdi!C10),"") | E24: =IFERROR(Girdi!E23/AVERAGE(Girdi!E10,Girdi!D10),"") | F24: Yılda kaç kez stok yenileniyor.
A25: Stokta kalma süresi (gün) | B25: 365 / Stok devir hızı | C25: =IFERROR(365*Girdi!C10/Girdi!C23,"") | D25: =IFERROR(365*AVERAGE(Girdi!D10,Girdi!C10)/Girdi!D23,"") | E25: =IFERROR(365*AVERAGE(Girdi!E10,Girdi!D10)/Girdi!E23,"") | F25: Uzaması talep zayıflığı veya eskiyen stok riski olabilir.
A26: Ticari borç ödeme süresi (gün) | B26: 365 x Ortalama ticari borçlar / Satışların maliyeti | C26: =IFERROR(365*Girdi!C15/Girdi!C23,"") | D26: =IFERROR(365*AVERAGE(Girdi!D15,Girdi!C15)/Girdi!D23,"") | E26: =IFERROR(365*AVERAGE(Girdi!E15,Girdi!D15)/Girdi!E23,"") | F26: Uzun olması tedarikçiye karşı pazarlık gücüne işaret eder.
A27: Nakit dönüşüm süresi (gün) | B27: Alacak süresi + Stok süresi - Borç süresi | C27: =IFERROR(C23+C25-C26,"") | D27: =IFERROR(D23+D25-D26,"") | E27: =IFERROR(E23+E25-E26,"") | F27: Kısa veya negatifse şirket büyürken nakit tüketmez. Uzaması işletme sermayesi ihtiyacını artırır.
A28: KARLILIK ORANLARI
A29: Brüt kar marjı | B29: (Hasılat - SMM) / Hasılat | C29: =IFERROR((Girdi!C22-Girdi!C23)/Girdi!C22,"") | D29: =IFERROR((Girdi!D22-Girdi!D23)/Girdi!D22,"") | E29: =IFERROR((Girdi!E22-Girdi!E23)/Girdi!E22,"") | F29: Fiyatlama gücünün ilk göstergesi. Yıllar içinde istikrarı seviyesinden önemli.
A30: FAVÖK marjı | B30: (Brüt kar - GYG - Pazarlama - ArGe + Amortisman) / Hasılat | C30: =IFERROR((Girdi!C22-Girdi!C23-Girdi!C24-Girdi!C25-Girdi!C26+Girdi!C29)/Girdi!C22,"") | D30: =IFERROR((Girdi!D22-Girdi!D23-Girdi!D24-Girdi!D25-Girdi!D26+Girdi!D29)/Girdi!D22,"") | E30: =IFERROR((Girdi!E22-Girdi!E23-Girdi!E24-Girdi!E25-Girdi!E26+Girdi!E29)/Girdi!E22,"") | F30: Diğer faaliyet gelir ve giderleri hariç tutulmuştur, böylece kur farkı gibi tek seferlik kalemler marjı bozmaz.
A31: Esas faaliyet kar marjı | B31: Esas faaliyet karı / Hasılat | C31: =IFERROR(Girdi!C27/Girdi!C22,"") | D31: =IFERROR(Girdi!D27/Girdi!D22,"") | E31: =IFERROR(Girdi!E27/Girdi!E22,"") | F31: FAVÖK marjından belirgin farklıysa diğer faaliyet gelir ve giderlerini dipnottan inceleyin.
A32: Net kar marjı | B32: Ana ortaklık net karı / Hasılat | C32: =IFERROR(Girdi!C34/Girdi!C22,"") | D32: =IFERROR(Girdi!D34/Girdi!D22,"") | E32: =IFERROR(Girdi!E34/Girdi!E22,"") | F32: Faaliyet marjından çok yüksekse karın kaynağı faaliyet dışı olabilir.
A33: Özkaynak karlılığı (ROE) | B33: Ana ortaklık net karı / Ort. ana ortaklık özkaynakları | C33: =IFERROR(Girdi!C34/Girdi!C19,"") | D33: =IFERROR(Girdi!D34/AVERAGE(Girdi!D19,Girdi!C19),"") | E33: =IFERROR(Girdi!E34/AVERAGE(Girdi!E19,Girdi!D19),"") | F33: Enflasyonun ve faiz oranının üzerinde olması beklenir. Yüksek kaldıraçla şişebilir.
A34: Aktif karlılığı (ROA) | B34: Dönem karı / Ortalama toplam varlıklar | C34: =IFERROR(Girdi!C33/Girdi!C13,"") | D34: =IFERROR(Girdi!D33/AVERAGE(Girdi!D13,Girdi!C13),"") | E34: =IFERROR(Girdi!E33/AVERAGE(Girdi!E13,Girdi!D13),"") | F34: Kaldıraçtan bağımsız verimlilik ölçüsü.
A35: Efektif vergi oranı | B35: Vergi gideri / Vergi öncesi kar | C35: =IFERROR(Girdi!C32/Girdi!C31,"") | D35: =IFERROR(Girdi!D32/Girdi!D31,"") | E35: =IFERROR(Girdi!E32/Girdi!E31,"") | F35: Yasal oranın çok altındaysa teşvik veya ertelenmiş vergi etkisini dipnotta arayın.
A36: NOPAT (mn TL) | B36: Esas faaliyet karı x (1 - Efektif vergi oranı) | C36: =IFERROR(Girdi!C27*(1-Girdi!C32/Girdi!C31),"") | D36: =IFERROR(Girdi!D27*(1-Girdi!D32/Girdi!D31),"") | E36: =IFERROR(Girdi!E27*(1-Girdi!E32/Girdi!E31),"") | F36: Vergi sonrası faaliyet karı, ROIC hesabının payı.
A37: Yatırılan sermaye (mn TL) | B37: Toplam özkaynaklar + Net borç | C37: =IFERROR(Girdi!C20+(Girdi!C14+Girdi!C17-Girdi!C7-Girdi!C8),"") -> 0 | D37: =IFERROR(Girdi!D20+(Girdi!D14+Girdi!D17-Girdi!D7-Girdi!D8),"") -> 0 | E37: =IFERROR(Girdi!E20+(Girdi!E14+Girdi!E17-Girdi!E7-Girdi!E8),"") -> 0 | F37: Şirketin faaliyetine bağlanmış toplam sermaye.
A38: Yatırılan sermaye getirisi (ROIC) | B38: NOPAT / Ortalama yatırılan sermaye | C38: =IFERROR(C36/C37,"") | D38: =IFERROR(D36/AVERAGE(D37,C37),"") | E38: =IFERROR(E36/AVERAGE(E37,D37),"") | F38: Sermaye maliyetinin üzerinde kalıcı ROIC değer yaratan şirketi gösterir.
A39: NAKİT AKIŞI ORANLARI
A40: Serbest nakit akışı (mn TL) | B40: İşletme nakit akışı - CAPEX | C40: =IFERROR(Girdi!C36-Girdi!C37,"") -> 0 | D40: =IFERROR(Girdi!D36-Girdi!D37,"") -> 0 | E40: =IFERROR(Girdi!E36-Girdi!E37,"") -> 0 | F40: Kalıcı negatif SNA borç veya sermaye artırımıyla finanse edilen büyüme demektir.
A41: SNA marjı | B41: SNA / Hasılat | C41: =IFERROR((Girdi!C36-Girdi!C37)/Girdi!C22,"") | D41: =IFERROR((Girdi!D36-Girdi!D37)/Girdi!D22,"") | E41: =IFERROR((Girdi!E36-Girdi!E37)/Girdi!E22,"") | F41: Satışların ne kadarının gerçek nakde döndüğü.
...

Sheet Kontrol
A1: Girdi Kontrolleri
A3: Kontrol | C3: Dönem 1 | D3: Dönem 2 | E3: Dönem 3
A4: Toplam varlıklar = KV + UV yükümlülükler + Özkaynaklar | C4: =IF(Girdi!C13="","",IF(ABS(Girdi!C13-Girdi!C16-Girdi!C18-Girdi!C20)<=0.01*Girdi!C13,"TAMAM","UYARI")) | D4: =IF(Girdi!D13="","",IF(ABS(Girdi!D13-Girdi!D16-Girdi!D18-Girdi!D20)<=0.01*Girdi!D13,"TAMAM","UYARI")) | E4: =IF(Girdi!E13="","",IF(ABS(Girdi!E13-Girdi!E16-Girdi!E18-Girdi!E20)<=0.01*Girdi!E13,"TAMAM","UYARI"))
A5: Dönen varlıklar toplam varlıklardan küçük | C5: =IF(Girdi!C13="","",IF(Girdi!C11<Girdi!C13,"TAMAM","UYARI")) | D5: =IF(Girdi!D13="","",IF(Girdi!D11<Girdi!D13,"TAMAM","UYARI")) | E5: =IF(Girdi!E13="","",IF(Girdi!E11<Girdi!E13,"TAMAM","UYARI"))
A6: Ana ortaklık özkaynağı toplam özkaynaktan büyük değil | C6: =IF(Girdi!C20="","",IF(Girdi!C19<=Girdi!C20+0.5,"TAMAM","UYARI")) | D6: =IF(Girdi!D20="","",IF(Girdi!D19<=Girdi!D20+0.5,"TAMAM","UYARI")) | E6: =IF(Girdi!E20="","",IF(Girdi!E19<=Girdi!E20+0.5,"TAMAM","UYARI"))
A7: Giderler pozitif girilmiş (SMM, GYG, pazarlama) | C7: =IF(Girdi!C22="","",IF(AND(Girdi!C23>=0,Girdi!C24>=0,Girdi!C25>=0),"TAMAM","UYARI")) | D7: =IF(Girdi!D22="","",IF(AND(Girdi!D23>=0,Girdi!D24>=0,Girdi!D25>=0),"TAMAM","UYARI")) | E7: =IF(Girdi!E22="","",IF(AND(Girdi!E23>=0,Girdi!E24>=0,Girdi!E25>=0),"TAMAM","UYARI"))
A8: CAPEX ve temettü pozitif girilmiş | C8: =IF(Girdi!C36="","",IF(AND(Girdi!C37>=0,Girdi!C38>=0),"TAMAM","UYARI")) | D8: =IF(Girdi!D36="","",IF(AND(Girdi!D37>=0,Girdi!D38>=0),"TAMAM","UYARI")) | E8: =IF(Girdi!E36="","",IF(AND(Girdi!E37>=0,Girdi!E38>=0),"TAMAM","UYARI"))
A10: Bilanço denkliğinde yüzde 1 sapma toleransı kullanılır, yuvarlamadan kaynaklı farklar UYARI vermez.
